Traceback (most recent call last):
  File "/opt/hostedtoolcache/Python/3.8.16/x64/lib/python3.8/site-packages/jupyter_cache/executors/utils.py", line 51, in single_nb_execution
    executenb(
  File "/opt/hostedtoolcache/Python/3.8.16/x64/lib/python3.8/site-packages/nbclient/client.py", line 1204, in execute
    return NotebookClient(nb=nb, resources=resources, km=km, **kwargs).execute()
  File "/opt/hostedtoolcache/Python/3.8.16/x64/lib/python3.8/site-packages/nbclient/util.py", line 84, in wrapped
    return just_run(coro(*args, **kwargs))
  File "/opt/hostedtoolcache/Python/3.8.16/x64/lib/python3.8/site-packages/nbclient/util.py", line 62, in just_run
    return loop.run_until_complete(coro)
  File "/opt/hostedtoolcache/Python/3.8.16/x64/lib/python3.8/asyncio/base_events.py", line 616, in run_until_complete
    return future.result()
  File "/opt/hostedtoolcache/Python/3.8.16/x64/lib/python3.8/site-packages/nbclient/client.py", line 663, in async_execute
    await self.async_execute_cell(
  File "/opt/hostedtoolcache/Python/3.8.16/x64/lib/python3.8/site-packages/nbclient/client.py", line 965, in async_execute_cell
    await self._check_raise_for_error(cell, cell_index, exec_reply)
  File "/opt/hostedtoolcache/Python/3.8.16/x64/lib/python3.8/site-packages/nbclient/client.py", line 862, in _check_raise_for_error
    raise CellExecutionError.from_cell_and_msg(cell, exec_reply_content)
nbclient.exceptions.CellExecutionError: An error occurred while executing the following cell:
------------------
for sub_ses in sub_ses_set:
    base_dir = os.getcwd()
    sub = sub_ses[0]
    ses = sub_ses[1]
    os.chdir('sub-'+sub+'_ses-'+ses+'/metrics/')
    if int(sub) == 1 and int(ses) ==1:
        foo = labels.Labels(label, metrics)
    else:
        foo = labels.Labels(label, metrics, Path(base_dir) / 'database.csv')
    foo.set_stats('fa', 3, int(sub), int(ses))
    foo.set_stats('fa', 4, int(sub), int(ses))
    foo.set_stats('fa', 5, int(sub), int(ses))
    foo.set_stats('md', 3, int(sub), int(ses))
    foo.set_stats('md', 4, int(sub), int(ses))
    foo.set_stats('md', 5, int(sub), int(ses))
    foo.set_stats('rd', 3, int(sub), int(ses))
    foo.set_stats('rd', 4, int(sub), int(ses))
    foo.set_stats('rd', 5, int(sub), int(ses))
    foo.save_stats(Path(base_dir) / 'database.csv')
    os.chdir(base_dir)

------------------

[0;31m---------------------------------------------------------------------------[0m
[0;31mFileNotFoundError[0m                         Traceback (most recent call last)
Cell [0;32mIn[3], line 5[0m
[1;32m      3[0m sub [38;5;241m=[39m sub_ses[[38;5;241m0[39m]
[1;32m      4[0m ses [38;5;241m=[39m sub_ses[[38;5;241m1[39m]
[0;32m----> 5[0m [43mos[49m[38;5;241;43m.[39;49m[43mchdir[49m[43m([49m[38;5;124;43m'[39;49m[38;5;124;43msub-[39;49m[38;5;124;43m'[39;49m[38;5;241;43m+[39;49m[43msub[49m[38;5;241;43m+[39;49m[38;5;124;43m'[39;49m[38;5;124;43m_ses-[39;49m[38;5;124;43m'[39;49m[38;5;241;43m+[39;49m[43mses[49m[38;5;241;43m+[39;49m[38;5;124;43m'[39;49m[38;5;124;43m/metrics/[39;49m[38;5;124;43m'[39;49m[43m)[49m
[1;32m      6[0m [38;5;28;01mif[39;00m [38;5;28mint[39m(sub) [38;5;241m==[39m [38;5;241m1[39m [38;5;129;01mand[39;00m [38;5;28mint[39m(ses) [38;5;241m==[39m[38;5;241m1[39m:
[1;32m      7[0m     foo [38;5;241m=[39m labels[38;5;241m.[39mLabels(label, metrics)

[0;31mFileNotFoundError[0m: [Errno 2] No such file or directory: 'sub-01_ses-001/metrics/'
FileNotFoundError: [Errno 2] No such file or directory: 'sub-01_ses-001/metrics/'

